2025-04-15 22:50:12,770 - run_script - INFO - Running run_script
2025-04-15 22:50:12,771 - run_script - INFO - Finished run_script
2025-04-15 22:50:12,771 - __main__ - WARNING - [2_PROCESS] Running script...
2025-04-15 22:50:12,771 - __main__ - ERROR - [2_PROCESS] Error processing file ./file path 1: object of type 'NoneType' has no len()

Traceback:
Traceback (most recent call last):
  File "/Users/ruka/Desktop/rag-fact-sheets-4/entrypoints/2_process.py", line 34, in process_file_one
    logger.info(f"[2_PROCESS] Chunked {len(chunks)} chunks from {file_path}, validating chunks...")
                                       ~~~^^^^^^^^
TypeError: object of type 'NoneType' has no len()

2025-04-15 22:50:12,772 - __main__ - ERROR - [2_PROCESS] Error processing file ./file path 2: object of type 'NoneType' has no len()

Traceback:
Traceback (most recent call last):
  File "/Users/ruka/Desktop/rag-fact-sheets-4/entrypoints/2_process.py", line 34, in process_file_one
    logger.info(f"[2_PROCESS] Chunked {len(chunks)} chunks from {file_path}, validating chunks...")
                                       ~~~^^^^^^^^
TypeError: object of type 'NoneType' has no len()

2025-04-15 22:50:12,772 - __main__ - ERROR - [2_PROCESS] Error processing file ./file path 3: object of type 'NoneType' has no len()

Traceback:
Traceback (most recent call last):
  File "/Users/ruka/Desktop/rag-fact-sheets-4/entrypoints/2_process.py", line 34, in process_file_one
    logger.info(f"[2_PROCESS] Chunked {len(chunks)} chunks from {file_path}, validating chunks...")
                                       ~~~^^^^^^^^
TypeError: object of type 'NoneType' has no len()

2025-04-15 22:50:12,772 - __main__ - WARNING - [2_PROCESS] Script completed successfully
2025-04-15 23:06:41,003 - run_script - INFO - Running run_script
2025-04-15 23:06:41,003 - run_script - INFO - Finished run_script
2025-04-15 23:06:41,004 - __main__ - WARNING - 

[2_PROCESS] Running script...
2025-04-15 23:06:41,004 - __main__ - INFO - [2_PROCESS] Chunked 3 chunks from ./file path 1, validating chunks...
2025-04-15 23:06:41,006 - __main__ - ERROR - [2_PROCESS] Error processing file ./file path 1: 1 validation error for ChunkModel
placeholder
  Input should be a valid string [type=string_type, input_value={'key1': 'value1', 'key2'...d_key': 'nested_value'}}, input_type=dict]
    For further information visit https://errors.pydantic.dev/2.11/v/string_type

Traceback:
Traceback (most recent call last):
  File "/Users/ruka/Desktop/rag-fact-sheets-4/entrypoints/2_process.py", line 36, in process_file_one
    validated_chunk = ChunkModel(placeholder=chunk)
  File "/Users/ruka/Desktop/rag-fact-sheets-4/group4venv/lib/python3.13/site-packages/pydantic/main.py", line 253, in __init__
    validated_self = self.__pydantic_validator__.validate_python(data, self_instance=self)
pydantic_core._pydantic_core.ValidationError: 1 validation error for ChunkModel
placeholder
  Input should be a valid string [type=string_type, input_value={'key1': 'value1', 'key2'...d_key': 'nested_value'}}, input_type=dict]
    For further information visit https://errors.pydantic.dev/2.11/v/string_type

2025-04-15 23:06:41,006 - __main__ - INFO - [2_PROCESS] Chunked 3 chunks from ./file path 2, validating chunks...
2025-04-15 23:06:41,006 - __main__ - ERROR - [2_PROCESS] Error processing file ./file path 2: 1 validation error for ChunkModel
placeholder
  Input should be a valid string [type=string_type, input_value={'key1': 'value1', 'key2'...d_key': 'nested_value'}}, input_type=dict]
    For further information visit https://errors.pydantic.dev/2.11/v/string_type

Traceback:
Traceback (most recent call last):
  File "/Users/ruka/Desktop/rag-fact-sheets-4/entrypoints/2_process.py", line 36, in process_file_one
    validated_chunk = ChunkModel(placeholder=chunk)
  File "/Users/ruka/Desktop/rag-fact-sheets-4/group4venv/lib/python3.13/site-packages/pydantic/main.py", line 253, in __init__
    validated_self = self.__pydantic_validator__.validate_python(data, self_instance=self)
pydantic_core._pydantic_core.ValidationError: 1 validation error for ChunkModel
placeholder
  Input should be a valid string [type=string_type, input_value={'key1': 'value1', 'key2'...d_key': 'nested_value'}}, input_type=dict]
    For further information visit https://errors.pydantic.dev/2.11/v/string_type

2025-04-15 23:06:41,006 - __main__ - INFO - [2_PROCESS] Chunked 3 chunks from ./file path 3, validating chunks...
2025-04-15 23:06:41,006 - __main__ - ERROR - [2_PROCESS] Error processing file ./file path 3: 1 validation error for ChunkModel
placeholder
  Input should be a valid string [type=string_type, input_value={'key1': 'value1', 'key2'...d_key': 'nested_value'}}, input_type=dict]
    For further information visit https://errors.pydantic.dev/2.11/v/string_type

Traceback:
Traceback (most recent call last):
  File "/Users/ruka/Desktop/rag-fact-sheets-4/entrypoints/2_process.py", line 36, in process_file_one
    validated_chunk = ChunkModel(placeholder=chunk)
  File "/Users/ruka/Desktop/rag-fact-sheets-4/group4venv/lib/python3.13/site-packages/pydantic/main.py", line 253, in __init__
    validated_self = self.__pydantic_validator__.validate_python(data, self_instance=self)
pydantic_core._pydantic_core.ValidationError: 1 validation error for ChunkModel
placeholder
  Input should be a valid string [type=string_type, input_value={'key1': 'value1', 'key2'...d_key': 'nested_value'}}, input_type=dict]
    For further information visit https://errors.pydantic.dev/2.11/v/string_type

2025-04-15 23:06:41,006 - __main__ - WARNING - [2_PROCESS] Script completed successfully
2025-04-15 23:24:29,150 - run_script - INFO - Running run_script
2025-04-15 23:24:29,150 - run_script - INFO - Finished run_script
2025-04-15 23:24:29,150 - __main__ - WARNING - 

[2_PROCESS] Running script...
2025-04-15 23:24:29,150 - __main__ - INFO - [2_PROCESS] Chunked 3 chunks from ./file path 1, validating chunks...
2025-04-15 23:24:29,151 - __main__ - ERROR - [2_PROCESS] Error processing file ./file path 1: 'dict' object has no attribute 'cleaning_function'

Traceback:
Traceback (most recent call last):
  File "/Users/ruka/Desktop/rag-fact-sheets-4/entrypoints/2_process.py", line 39, in process_file_one
    cleaned = chunk.cleaning_function(chunks)
              ^^^^^^^^^^^^^^^^^^^^^^^
AttributeError: 'dict' object has no attribute 'cleaning_function'

2025-04-15 23:24:29,151 - __main__ - INFO - [2_PROCESS] Chunked 3 chunks from ./file path 2, validating chunks...
2025-04-15 23:24:29,151 - __main__ - ERROR - [2_PROCESS] Error processing file ./file path 2: 'dict' object has no attribute 'cleaning_function'

Traceback:
Traceback (most recent call last):
  File "/Users/ruka/Desktop/rag-fact-sheets-4/entrypoints/2_process.py", line 39, in process_file_one
    cleaned = chunk.cleaning_function(chunks)
              ^^^^^^^^^^^^^^^^^^^^^^^
AttributeError: 'dict' object has no attribute 'cleaning_function'

2025-04-15 23:24:29,151 - __main__ - INFO - [2_PROCESS] Chunked 3 chunks from ./file path 3, validating chunks...
2025-04-15 23:24:29,152 - __main__ - ERROR - [2_PROCESS] Error processing file ./file path 3: 'dict' object has no attribute 'cleaning_function'

Traceback:
Traceback (most recent call last):
  File "/Users/ruka/Desktop/rag-fact-sheets-4/entrypoints/2_process.py", line 39, in process_file_one
    cleaned = chunk.cleaning_function(chunks)
              ^^^^^^^^^^^^^^^^^^^^^^^
AttributeError: 'dict' object has no attribute 'cleaning_function'

2025-04-15 23:24:29,152 - __main__ - WARNING - [2_PROCESS] Script completed successfully
2025-04-15 23:47:14,030 - run_script - INFO - Running run_script
2025-04-15 23:47:14,030 - run_script - INFO - Finished run_script
2025-04-15 23:47:14,030 - __main__ - WARNING - 

[2_PROCESS] Running script...
2025-04-15 23:47:14,030 - __main__ - INFO - [2_PROCESS] Chunked 3 chunks from ./file path 1, validating chunks...
2025-04-15 23:47:14,031 - __main__ - ERROR - [2_PROCESS] Error processing file ./file path 1: 'dict' object has no attribute 'cleaning_function'

Traceback:
Traceback (most recent call last):
  File "/Users/ruka/Desktop/rag-fact-sheets-4/entrypoints/2_process.py", line 39, in process_file_one
    cleaned = chunk.cleaning_function(chunks)
              ^^^^^^^^^^^^^^^^^^^^^^^
AttributeError: 'dict' object has no attribute 'cleaning_function'

2025-04-15 23:47:14,031 - __main__ - INFO - [2_PROCESS] Chunked 3 chunks from ./file path 2, validating chunks...
2025-04-15 23:47:14,031 - __main__ - ERROR - [2_PROCESS] Error processing file ./file path 2: 'dict' object has no attribute 'cleaning_function'

Traceback:
Traceback (most recent call last):
  File "/Users/ruka/Desktop/rag-fact-sheets-4/entrypoints/2_process.py", line 39, in process_file_one
    cleaned = chunk.cleaning_function(chunks)
              ^^^^^^^^^^^^^^^^^^^^^^^
AttributeError: 'dict' object has no attribute 'cleaning_function'

2025-04-15 23:47:14,031 - __main__ - INFO - [2_PROCESS] Chunked 3 chunks from ./file path 3, validating chunks...
2025-04-15 23:47:14,031 - __main__ - ERROR - [2_PROCESS] Error processing file ./file path 3: 'dict' object has no attribute 'cleaning_function'

Traceback:
Traceback (most recent call last):
  File "/Users/ruka/Desktop/rag-fact-sheets-4/entrypoints/2_process.py", line 39, in process_file_one
    cleaned = chunk.cleaning_function(chunks)
              ^^^^^^^^^^^^^^^^^^^^^^^
AttributeError: 'dict' object has no attribute 'cleaning_function'

2025-04-15 23:47:14,032 - __main__ - WARNING - [2_PROCESS] Script completed successfully
2025-04-15 23:48:28,458 - run_script - INFO - Running run_script
2025-04-15 23:48:28,459 - run_script - INFO - Finished run_script
2025-04-15 23:48:28,459 - __main__ - WARNING - 

[2_PROCESS] Running script...
2025-04-15 23:48:28,459 - __main__ - ERROR - [2_PROCESS] Error processing file ./file path 1: object of type 'NoneType' has no len()

Traceback:
Traceback (most recent call last):
  File "/Users/ruka/Desktop/rag-fact-sheets-4/entrypoints/2_process.py", line 34, in process_file_one
    logger.info(f"[2_PROCESS] Chunked {len(chunks)} chunks from {file_path}, validating chunks...")
                                       ~~~^^^^^^^^
TypeError: object of type 'NoneType' has no len()

2025-04-15 23:48:28,460 - __main__ - ERROR - [2_PROCESS] Error processing file ./file path 2: object of type 'NoneType' has no len()

Traceback:
Traceback (most recent call last):
  File "/Users/ruka/Desktop/rag-fact-sheets-4/entrypoints/2_process.py", line 34, in process_file_one
    logger.info(f"[2_PROCESS] Chunked {len(chunks)} chunks from {file_path}, validating chunks...")
                                       ~~~^^^^^^^^
TypeError: object of type 'NoneType' has no len()

2025-04-15 23:48:28,460 - __main__ - ERROR - [2_PROCESS] Error processing file ./file path 3: object of type 'NoneType' has no len()

Traceback:
Traceback (most recent call last):
  File "/Users/ruka/Desktop/rag-fact-sheets-4/entrypoints/2_process.py", line 34, in process_file_one
    logger.info(f"[2_PROCESS] Chunked {len(chunks)} chunks from {file_path}, validating chunks...")
                                       ~~~^^^^^^^^
TypeError: object of type 'NoneType' has no len()

2025-04-15 23:48:28,460 - __main__ - WARNING - [2_PROCESS] Script completed successfully
2025-04-15 23:54:02,687 - run_script - INFO - Running run_script
2025-04-15 23:54:02,687 - run_script - INFO - Finished run_script
2025-04-15 23:54:02,687 - __main__ - WARNING - 

[2_PROCESS] Running script...
2025-04-15 23:54:02,688 - __main__ - INFO - [2_PROCESS] Chunked 3 chunks from ./file path 1, validating chunks...
2025-04-15 23:54:02,688 - __main__ - ERROR - [2_PROCESS] Error processing file ./file path 1: 'dict' object has no attribute 'cleaning_function'

Traceback:
Traceback (most recent call last):
  File "/Users/ruka/Desktop/rag-fact-sheets-4/entrypoints/2_process.py", line 39, in process_file_one
    cleaned = chunk.cleaning_function(chunks)
              ^^^^^^^^^^^^^^^^^^^^^^^
AttributeError: 'dict' object has no attribute 'cleaning_function'

2025-04-15 23:54:02,689 - __main__ - INFO - [2_PROCESS] Chunked 3 chunks from ./file path 2, validating chunks...
2025-04-15 23:54:02,689 - __main__ - ERROR - [2_PROCESS] Error processing file ./file path 2: 'dict' object has no attribute 'cleaning_function'

Traceback:
Traceback (most recent call last):
  File "/Users/ruka/Desktop/rag-fact-sheets-4/entrypoints/2_process.py", line 39, in process_file_one
    cleaned = chunk.cleaning_function(chunks)
              ^^^^^^^^^^^^^^^^^^^^^^^
AttributeError: 'dict' object has no attribute 'cleaning_function'

2025-04-15 23:54:02,689 - __main__ - INFO - [2_PROCESS] Chunked 3 chunks from ./file path 3, validating chunks...
2025-04-15 23:54:02,689 - __main__ - ERROR - [2_PROCESS] Error processing file ./file path 3: 'dict' object has no attribute 'cleaning_function'

Traceback:
Traceback (most recent call last):
  File "/Users/ruka/Desktop/rag-fact-sheets-4/entrypoints/2_process.py", line 39, in process_file_one
    cleaned = chunk.cleaning_function(chunks)
              ^^^^^^^^^^^^^^^^^^^^^^^
AttributeError: 'dict' object has no attribute 'cleaning_function'

2025-04-15 23:54:02,689 - __main__ - WARNING - [2_PROCESS] Script completed successfully
2025-04-15 23:58:01,664 - run_script - INFO - Running run_script
2025-04-15 23:58:01,665 - run_script - INFO - Finished run_script
2025-04-15 23:58:01,665 - __main__ - WARNING - 

[2_PROCESS] Running script...
2025-04-15 23:58:01,665 - __main__ - INFO - [2_PROCESS] Finished chunking ./file path 1, cleaning chunks...
2025-04-15 23:58:01,666 - __main__ - ERROR - [2_PROCESS] Error processing file ./file path 1: 'dict' object has no attribute 'cleaning_function'

Traceback:
Traceback (most recent call last):
  File "/Users/ruka/Desktop/rag-fact-sheets-4/entrypoints/2_process.py", line 39, in process_file_one
    cleaned = chunk.cleaning_function(chunks)
              ^^^^^^^^^^^^^^^^^^^^^^^
AttributeError: 'dict' object has no attribute 'cleaning_function'

2025-04-15 23:58:01,666 - __main__ - INFO - [2_PROCESS] Finished chunking ./file path 2, cleaning chunks...
2025-04-15 23:58:01,666 - __main__ - ERROR - [2_PROCESS] Error processing file ./file path 2: 'dict' object has no attribute 'cleaning_function'

Traceback:
Traceback (most recent call last):
  File "/Users/ruka/Desktop/rag-fact-sheets-4/entrypoints/2_process.py", line 39, in process_file_one
    cleaned = chunk.cleaning_function(chunks)
              ^^^^^^^^^^^^^^^^^^^^^^^
AttributeError: 'dict' object has no attribute 'cleaning_function'

2025-04-15 23:58:01,666 - __main__ - INFO - [2_PROCESS] Finished chunking ./file path 3, cleaning chunks...
2025-04-15 23:58:01,667 - __main__ - ERROR - [2_PROCESS] Error processing file ./file path 3: 'dict' object has no attribute 'cleaning_function'

Traceback:
Traceback (most recent call last):
  File "/Users/ruka/Desktop/rag-fact-sheets-4/entrypoints/2_process.py", line 39, in process_file_one
    cleaned = chunk.cleaning_function(chunks)
              ^^^^^^^^^^^^^^^^^^^^^^^
AttributeError: 'dict' object has no attribute 'cleaning_function'

2025-04-15 23:58:01,667 - __main__ - WARNING - [2_PROCESS] Script completed successfully
2025-04-15 23:59:45,349 - run_script - INFO - Running run_script
2025-04-15 23:59:45,349 - run_script - INFO - Finished run_script
2025-04-15 23:59:45,349 - __main__ - WARNING - 

[2_PROCESS] Running script...
2025-04-15 23:59:45,349 - __main__ - INFO - [2_PROCESS] Finished chunking ./file path 1, cleaning chunks...
2025-04-15 23:59:45,350 - __main__ - ERROR - [2_PROCESS] Error processing file ./file path 1: 'list' object has no attribute 'cleaning_function'

Traceback:
Traceback (most recent call last):
  File "/Users/ruka/Desktop/rag-fact-sheets-4/entrypoints/2_process.py", line 39, in process_file_one
    cleaned = chunks.cleaning_function(chunks)
              ^^^^^^^^^^^^^^^^^^^^^^^^
AttributeError: 'list' object has no attribute 'cleaning_function'

2025-04-15 23:59:45,350 - __main__ - INFO - [2_PROCESS] Finished chunking ./file path 2, cleaning chunks...
2025-04-15 23:59:45,351 - __main__ - ERROR - [2_PROCESS] Error processing file ./file path 2: 'list' object has no attribute 'cleaning_function'

Traceback:
Traceback (most recent call last):
  File "/Users/ruka/Desktop/rag-fact-sheets-4/entrypoints/2_process.py", line 39, in process_file_one
    cleaned = chunks.cleaning_function(chunks)
              ^^^^^^^^^^^^^^^^^^^^^^^^
AttributeError: 'list' object has no attribute 'cleaning_function'

2025-04-15 23:59:45,351 - __main__ - INFO - [2_PROCESS] Finished chunking ./file path 3, cleaning chunks...
2025-04-15 23:59:45,351 - __main__ - ERROR - [2_PROCESS] Error processing file ./file path 3: 'list' object has no attribute 'cleaning_function'

Traceback:
Traceback (most recent call last):
  File "/Users/ruka/Desktop/rag-fact-sheets-4/entrypoints/2_process.py", line 39, in process_file_one
    cleaned = chunks.cleaning_function(chunks)
              ^^^^^^^^^^^^^^^^^^^^^^^^
AttributeError: 'list' object has no attribute 'cleaning_function'

2025-04-15 23:59:45,351 - __main__ - WARNING - [2_PROCESS] Script completed successfully
2025-04-16 00:00:29,232 - run_script - INFO - Running run_script
2025-04-16 00:00:29,233 - run_script - INFO - Finished run_script
2025-04-16 00:00:29,233 - __main__ - WARNING - 

[2_PROCESS] Running script...
2025-04-16 00:00:29,233 - __main__ - INFO - [2_PROCESS] Finished chunking ./file path 1, cleaning chunks...
2025-04-16 00:00:29,234 - __main__ - INFO - [2_PROCESS] Finished cleaning chunks, embedding chunks...
2025-04-16 00:00:29,234 - __main__ - ERROR - [2_PROCESS] Error processing file ./file path 1: 'NoneType' object is not iterable

Traceback:
Traceback (most recent call last):
  File "/Users/ruka/Desktop/rag-fact-sheets-4/entrypoints/2_process.py", line 40, in process_file_one
    for embedding in embeddings:
                     ^^^^^^^^^^
TypeError: 'NoneType' object is not iterable

2025-04-16 00:00:29,234 - __main__ - INFO - [2_PROCESS] Finished chunking ./file path 2, cleaning chunks...
2025-04-16 00:00:29,234 - __main__ - INFO - [2_PROCESS] Finished cleaning chunks, embedding chunks...
2025-04-16 00:00:29,234 - __main__ - ERROR - [2_PROCESS] Error processing file ./file path 2: 'NoneType' object is not iterable

Traceback:
Traceback (most recent call last):
  File "/Users/ruka/Desktop/rag-fact-sheets-4/entrypoints/2_process.py", line 40, in process_file_one
    for embedding in embeddings:
                     ^^^^^^^^^^
TypeError: 'NoneType' object is not iterable

2025-04-16 00:00:29,234 - __main__ - INFO - [2_PROCESS] Finished chunking ./file path 3, cleaning chunks...
2025-04-16 00:00:29,234 - __main__ - INFO - [2_PROCESS] Finished cleaning chunks, embedding chunks...
2025-04-16 00:00:29,235 - __main__ - ERROR - [2_PROCESS] Error processing file ./file path 3: 'NoneType' object is not iterable

Traceback:
Traceback (most recent call last):
  File "/Users/ruka/Desktop/rag-fact-sheets-4/entrypoints/2_process.py", line 40, in process_file_one
    for embedding in embeddings:
                     ^^^^^^^^^^
TypeError: 'NoneType' object is not iterable

2025-04-16 00:00:29,235 - __main__ - WARNING - [2_PROCESS] Script completed successfully
2025-04-16 00:06:25,295 - run_script - INFO - Running run_script
2025-04-16 00:06:25,295 - run_script - INFO - Finished run_script
2025-04-16 00:06:25,295 - __main__ - WARNING - 

[2_PROCESS] Running script...
2025-04-16 00:06:25,296 - __main__ - INFO - [2_PROCESS] Finished chunking ./file path 1, cleaning chunks...
2025-04-16 00:06:25,296 - __main__ - INFO - [2_PROCESS] Finished cleaning chunks, embedding chunks...
2025-04-16 00:06:25,296 - database - INFO - [DATABASE] Uploading data into database...
2025-04-16 00:06:25,296 - database - INFO - [DATABASE] Uploaded database successfully.
2025-04-16 00:06:25,296 - __main__ - WARNING - [2_PROCESS] Uploaded chunks into database successfully
2025-04-16 00:06:25,296 - __main__ - WARNING - [2_PROCESS] File ./file path 1 processed successfully
2025-04-16 00:06:25,297 - __main__ - INFO - [2_PROCESS] Finished chunking ./file path 2, cleaning chunks...
2025-04-16 00:06:25,297 - __main__ - INFO - [2_PROCESS] Finished cleaning chunks, embedding chunks...
2025-04-16 00:06:25,297 - database - INFO - [DATABASE] Uploading data into database...
2025-04-16 00:06:25,297 - database - INFO - [DATABASE] Uploaded database successfully.
2025-04-16 00:06:25,297 - __main__ - WARNING - [2_PROCESS] Uploaded chunks into database successfully
2025-04-16 00:06:25,297 - __main__ - WARNING - [2_PROCESS] File ./file path 2 processed successfully
2025-04-16 00:06:25,297 - __main__ - INFO - [2_PROCESS] Finished chunking ./file path 3, cleaning chunks...
2025-04-16 00:06:25,297 - __main__ - INFO - [2_PROCESS] Finished cleaning chunks, embedding chunks...
2025-04-16 00:06:25,297 - database - INFO - [DATABASE] Uploading data into database...
2025-04-16 00:06:25,297 - database - INFO - [DATABASE] Uploaded database successfully.
2025-04-16 00:06:25,297 - __main__ - WARNING - [2_PROCESS] Uploaded chunks into database successfully
2025-04-16 00:06:25,297 - __main__ - WARNING - [2_PROCESS] File ./file path 3 processed successfully
2025-04-16 00:06:25,297 - __main__ - WARNING - [2_PROCESS] Script completed successfully
2025-04-16 00:09:25,986 - wrapper - INFO - Running wrapper
2025-04-16 00:09:28,988 - wrapper - INFO - Finished wrapper
2025-04-16 00:09:28,988 - __main__ - WARNING - 

[2_PROCESS] Running script...
2025-04-16 00:09:28,989 - __main__ - INFO - [2_PROCESS] Finished chunking ./file path 1, cleaning chunks...
2025-04-16 00:09:28,990 - __main__ - INFO - [2_PROCESS] Finished cleaning chunks, embedding chunks...
2025-04-16 00:09:28,990 - __main__ - WARNING - [2_PROCESS] File ./file path 1 processed successfully
2025-04-16 00:09:28,990 - __main__ - INFO - [2_PROCESS] Finished chunking ./file path 2, cleaning chunks...
2025-04-16 00:09:28,990 - __main__ - INFO - [2_PROCESS] Finished cleaning chunks, embedding chunks...
2025-04-16 00:09:28,990 - __main__ - WARNING - [2_PROCESS] File ./file path 2 processed successfully
2025-04-16 00:09:28,990 - __main__ - INFO - [2_PROCESS] Finished chunking ./file path 3, cleaning chunks...
2025-04-16 00:09:28,990 - __main__ - INFO - [2_PROCESS] Finished cleaning chunks, embedding chunks...
2025-04-16 00:09:28,991 - __main__ - WARNING - [2_PROCESS] File ./file path 3 processed successfully
2025-04-16 00:09:28,991 - __main__ - INFO - [2_PROCESS] Uploading chunks into database...
2025-04-16 00:09:28,991 - database - INFO - [DATABASE] Uploading data into database...
2025-04-16 00:09:28,991 - database - INFO - [DATABASE] Uploaded database successfully.
2025-04-16 00:09:28,991 - __main__ - WARNING - [2_PROCESS] Uploaded chunks into database successfully
2025-04-16 00:09:28,991 - __main__ - WARNING - [2_PROCESS] Script completed successfully
2025-04-16 00:14:32,926 - wrapper - INFO - Running wrapper
2025-04-16 00:14:35,928 - wrapper - INFO - Finished wrapper
2025-04-16 00:14:35,929 - entrypoints.2_process - WARNING - 

[2_PROCESS] Running script...
2025-04-16 00:14:35,929 - entrypoints.2_process - INFO - [2_PROCESS] Finished chunking ./file path 1, cleaning chunks...
2025-04-16 00:14:35,931 - entrypoints.2_process - INFO - [2_PROCESS] Finished cleaning chunks, embedding chunks...
2025-04-16 00:14:35,931 - entrypoints.2_process - WARNING - [2_PROCESS] File ./file path 1 processed successfully
2025-04-16 00:14:35,931 - entrypoints.2_process - INFO - [2_PROCESS] Finished chunking ./file path 2, cleaning chunks...
2025-04-16 00:14:35,931 - entrypoints.2_process - INFO - [2_PROCESS] Finished cleaning chunks, embedding chunks...
2025-04-16 00:14:35,931 - entrypoints.2_process - WARNING - [2_PROCESS] File ./file path 2 processed successfully
2025-04-16 00:14:35,931 - entrypoints.2_process - INFO - [2_PROCESS] Finished chunking ./file path 3, cleaning chunks...
2025-04-16 00:14:35,931 - entrypoints.2_process - INFO - [2_PROCESS] Finished cleaning chunks, embedding chunks...
2025-04-16 00:14:35,931 - entrypoints.2_process - WARNING - [2_PROCESS] File ./file path 3 processed successfully
2025-04-16 00:14:35,931 - entrypoints.2_process - INFO - [2_PROCESS] Uploading chunks into database...
2025-04-16 00:14:35,931 - database - INFO - [DATABASE] Uploading data into database...
2025-04-16 00:14:35,931 - database - INFO - [DATABASE] Uploaded database successfully.
2025-04-16 00:14:35,932 - entrypoints.2_process - WARNING - [2_PROCESS] Uploaded chunks into database successfully
2025-04-16 00:14:35,932 - entrypoints.2_process - WARNING - [2_PROCESS] Script completed successfully
